Workbook

Sheet Summary
A1: WholeCart – Test Summary
A3: Project | B3: WholeCart B2B marketplace – Phase 1
A4: Specification | B4: Functional design v1.0 (WC-FDD-1.0-641d)
A5: Environment | B5: QA - http://13.200.185.1/c/purushoth-kumar-efaa03 | Chrome, macOS
A6: Accounts used | B6: buyer1 (Spice Route Kitchen), buyer2 (Café Dosa Corner), seller1 (WholeCart Direct), operator
A7: Test date | B7: 2026-10-14
A9: Overall
A10: Item | B10: Count
A11: Test cases | B11: =COUNTA(Testcases!$A:$A)-1
A12: Passed | B12: =COUNTIF(Testcases!$M:$M,"Pass")
A13: Failed | B13: =COUNTIF(Testcases!$M:$M,"Fail")
A14: Pass rate | B14: =IF(B11=0,"",B12/B11)
A15: Defects logged | B15: =COUNTA(Bugs!$A:$A)-1
A16: Defects open | B16: =COUNTIF(Bugs!$O:$O,"Open")
A18: Test execution by module
A19: Module | B19: Total | C19: Pass | D19: Fail | E19: Pass % | F19: Defects
A20: Login & Access | B20: =COUNTIF(Testcases!$B:$B,$A20) | C20: =COUNTIFS(Testcases!$B:$B,$A20,Testcases!$M:$M,"Pass") | D20: =COUNTIFS(Testcases!$B:$B,$A20,Testcases!$M:$M,"Fail") | E20: =IF(B20=0,"",C20/B20) | F20: =COUNTIF(Bugs!$B:$B,$A20)
A21: Catalogue & Search | B21: =COUNTIF(Testcases!$B:$B,$A21) | C21: =COUNTIFS(Testcases!$B:$B,$A21,Testcases!$M:$M,"Pass") | D21: =COUNTIFS(Testcases!$B:$B,$A21,Testcases!$M:$M,"Fail") | E21: =IF(B21=0,"",C21/B21) | F21: =COUNTIF(Bugs!$B:$B,$A21)
A22: Cart | B22: =COUNTIF(Testcases!$B:$B,$A22) | C22: =COUNTIFS(Testcases!$B:$B,$A22,Testcases!$M:$M,"Pass") | D22: =COUNTIFS(Testcases!$B:$B,$A22,Testcases!$M:$M,"Fail") | E22: =IF(B22=0,"",C22/B22) | F22: =COUNTIF(Bugs!$B:$B,$A22)
A23: Checkout | B23: =COUNTIF(Testcases!$B:$B,$A23) | C23: =COUNTIFS(Testcases!$B:$B,$A23,Testcases!$M:$M,"Pass") | D23: =COUNTIFS(Testcases!$B:$B,$A23,Testcases!$M:$M,"Fail") | E23: =IF(B23=0,"",C23/B23) | F23: =COUNTIF(Bugs!$B:$B,$A23)
A24: Delivery Slots | B24: =COUNTIF(Testcases!$B:$B,$A24) | C24: =COUNTIFS(Testcases!$B:$B,$A24,Testcases!$M:$M,"Pass") | D24: =COUNTIFS(Testcases!$B:$B,$A24,Testcases!$M:$M,"Fail") | E24: =IF(B24=0,"",C24/B24) | F24: =COUNTIF(Bugs!$B:$B,$A24)
A25: Order History | B25: =COUNTIF(Testcases!$B:$B,$A25) | C25: =COUNTIFS(Testcases!$B:$B,$A25,Testcases!$M:$M,"Pass") | D25: =COUNTIFS(Testcases!$B:$B,$A25,Testcases!$M:$M,"Fail") | E25: =IF(B25=0,"",C25/B25) | F25: =COUNTIF(Bugs!$B:$B,$A25)
A26: Cancellation | B26: =COUNTIF(Testcases!$B:$B,$A26) | C26: =COUNTIFS(Testcases!$B:$B,$A26,Testcases!$M:$M,"Pass") | D26: =COUNTIFS(Testcases!$B:$B,$A26,Testcases!$M:$M,"Fail") | E26: =IF(B26=0,"",C26/B26) | F26: =COUNTIF(Bugs!$B:$B,$A26)
A27: Slot Change | B27: =COUNTIF(Testcases!$B:$B,$A27) | C27: =COUNTIFS(Testcases!$B:$B,$A27,Testcases!$M:$M,"Pass") | D27: =COUNTIFS(Testcases!$B:$B,$A27,Testcases!$M:$M,"Fail") | E27: =IF(B27=0,"",C27/B27) | F27: =COUNTIF(Bugs!$B:$B,$A27)
A28: Redelivery | B28: =COUNTIF(Testcases!$B:$B,$A28) | C28: =COUNTIFS(Testcases!$B:$B,$A28,Testcases!$M:$M,"Pass") | D28: =COUNTIFS(Testcases!$B:$B,$A28,Testcases!$M:$M,"Fail") | E28: =IF(B28=0,"",C28/B28) | F28: =COUNTIF(Bugs!$B:$B,$A28)
A29: Reorder | B29: =COUNTIF(Testcases!$B:$B,$A29) | C29: =COUNTIFS(Testcases!$B:$B,$A29,Testcases!$M:$M,"Pass") | D29: =COUNTIFS(Testcases!$B:$B,$A29,Testcases!$M:$M,"Fail") | E29: =IF(B29=0,"",C29/B29) | F29: =COUNTIF(Bugs!$B:$B,$A29)
A30: Refunds & Exchanges | B30: =COUNTIF(Testcases!$B:$B,$A30) | C30: =COUNTIFS(Testcases!$B:$B,$A30,Testcases!$M:$M,"Pass") | D30: =COUNTIFS(Testcases!$B:$B,$A30,Testcases!$M:$M,"Fail") | E30: =IF(B30=0,"",C30/B30) | F30: =COUNTIF(Bugs!$B:$B,$A30)
A31: Invoices | B31: =COUNTIF(Testcases!$B:$B,$A31) | C31: =COUNTIFS(Testcases!$B:$B,$A31,Testcases!$M:$M,"Pass") | D31: =COUNTIFS(Testcases!$B:$B,$A31,Testcases!$M:$M,"Fail") | E31: =IF(B31=0,"",C31/B31) | F31: =COUNTIF(Bugs!$B:$B,$A31)
... A37: Operator | B37: =COUNTIF(Testcases!$B:$B,$A37) | C37: =COUNTIFS(Testcases!$B:$B,$A37,Testcases!$M:$M,"Pass") | D37: =COUNTIFS(Testcases!$B:$B,$A37,Testcases!$M:$M,"Fail") | E37: =IF(B37=0,"",C37/B37) | F37: =COUNTIF(Bugs!$B:$B,$A37)
A38: Total | B38: =SUM(B20:B37) | C38: =SUM(C20:C37) | D38: =SUM(D20:D37) | E38: =IF(B38=0,"",C38/B38) | F38: =SUM(F20:F37)
A40: Test cases by user type
A41: User type | B41: Total | C41: Pass | D41: Fail
A42: Buyer | B42: =COUNTIF(Testcases!$C:$C,$A42) | C42: =COUNTIFS(Testcases!$C:$C,$A42,Testcases!$M:$M,"Pass") | D42: =COUNTIFS(Testcases!$C:$C,$A42,Testcases!$M:$M,"Fail")
A43: Buyer, Operator | B43: =COUNTIF(Testcases!$C:$C,$A43) | C43: =COUNTIFS(Testcases!$C:$C,$A43,Testcases!$M:$M,"Pass") | D43: =COUNTIFS(Testcases!$C:$C,$A43,Testcases!$M:$M,"Fail")
A44: Buyer, Seller | B44: =COUNTIF(Testcases!$C:$C,$A44) | C44: =COUNTIFS(Testcases!$C:$C,$A44,Testcases!$M:$M,"Pass") | D44: =COUNTIFS(Testcases!$C:$C,$A44,Testcases!$M:$M,"Fail")
A45: Seller | B45: =COUNTIF(Testcases!$C:$C,$A45) | C45: =COUNTIFS(Testcases!$C:$C,$A45,Testcases!$M:$M,"Pass") | D45: =COUNTIFS(Testcases!$C:$C,$A45,Testcases!$M:$M,"Fail")
A46: Operator | B46: =COUNTIF(Testcases!$C:$C,$A46) | C46: =COUNTIFS(Testcases!$C:$C,$A46,Testcases!$M:$M,"Pass") | D46: =COUNTIFS(Testcases!$C:$C,$A46,Testcases!$M:$M,"Fail")
A48: Defects by severity and priority
A49: Severity | B49: High | C49: Medium | D49: Low | E49: Total
A50: Critical | B50: =COUNTIFS(Bugs!$J:$J,$A50,Bugs!$K:$K,"High") | C50: =COUNTIFS(Bugs!$J:$J,$A50,Bugs!$K:$K,"Medium") | D50: =COUNTIFS(Bugs!$J:$J,$A50,Bugs!$K:$K,"Low") | E50: =COUNTIF(Bugs!$J:$J,$A50)
...

Sheet Testcases
A1: Test Case ID | B1: Module | C1: User Type | D1: Test Case Title | E1: Test Case Description | F1: Test Case Type | G1: Preconditions | H1: Test Steps | I1: Test Data | J1: Expected Result | K1: Actual Result | L1: Application Environment | M1: Status | N1: Priority | O1: Bug ID
A2: TC-01-01 | B2: Login & Access | C2: Buyer | D2: Buyer logs in with valid credentials | E2: Verify buyer login with valid credentials. | F2: Positive | G2: App URL reachable | H2: 1. Open /login 2. Enter username and password 3. Click Log in | I2: buyer1 / Test@123 | J2: Buyer should be logged in and taken to the Catalogue. Header should show 'Spice Route Kitchen' and a Log out link. | K2: Login works. Buyer header shows 'Spice Route Kitchen'; seller login shows 'WholeCart Direct'. | L2: QA - http://13.200.185.1/c/purushoth-kumar-efaa03 | Chrome, macOS | M2: Pass | N2: High
A3: TC-01-02 | B3: Login & Access | C3: Buyer | D3: Buyer cannot open another buyer's order (BR-21) | E3: Verify a buyer cannot see another buyer's orders. | F3: Negative | G3: buyer2 has an order; note its id (e.g. /orders/7) | H3: 1. Log in as buyer1 2. Open buyer2's order URL /orders/{id} 3. Try the same for /invoices/{id} | I3: buyer1, buyer2 order id | J3: Access should be denied (403/404). No order, invoice or statement details of the other buyer should be shown. | K3: Access was denied. No order, invoice or statement details of the other buyer were shown. | L3: QA - http://13.200.185.1/c/purushoth-kumar-efaa03 | Chrome, macOS | M3: Pass | N3: High
A4: TC-02-01 | B4: Catalogue & Search | C4: Buyer | D4: Out-of-stock products never shown (BR-02) | E4: Verify out-of-stock products are hidden from the catalogue. | F4: Negative | G4: Logged in as buyer1; seller1 (WholeCart Direct) products SKU-0030 and SKU-0047 have stock 0 | H4: 1. As seller1, open Products and note SKU-0030 and SKU-0047 have stock 0 2. As buyer1, open Catalogue 3. Search SKU-0030, then SKU-0047 4. Open the product page | I4: SKU-0030 Spice Toor Dal (stock 0), SKU-0047 Prime Moong Dal (stock 0) | J4: The product should not appear in the catalogue list, in search results or under its category. The product count should not include it. | K4: SKU-0030 Spice Toor Dal and SKU-0047 Prime Moong Dal have 0 stock but still appear in catalogue search. The product page shows 'In stock: 0 pieces' with Add to cart enabled. | L4: QA - http://13.200.185.1/c/purushoth-kumar-efaa03 | Chrome, macOS | M4: Fail | N4: High | O4: DEF-016
A5: TC-02-02 | B5: Catalogue & Search | C5: Buyer | D5: Category filter combined with search text | E5: Verify search text and category filter work together. | F5: Positive | G5: Logged in as buyer1 (Spice Route Kitchen) / Test@123 | H5: 1. Type search text 2. Select category 3. Click Search | I5: Chef + Oils | J5: Only products matching both the search text and the selected category should be shown (e.g. Chef's Coconut Oil, Chef's Mustard Oil). The product count should match the list. | K5: Search 'Chef' with category 'Oils' still showed 28 products from all categories. Needs re-check. | L5: QA - http://13.200.185.1/c/purushoth-kumar-efaa03 | Chrome, macOS | M5: Fail | N5: High | O5: DEF-006
A6: TC-03-01 | B6: Cart | C6: Buyer | D6: Quantity control is a dropdown 1-20 (5.1) | E6: Verify the cart quantity control is a 1-20 dropdown. | F6: Positive | G6: Cart has one line | H6: 1. Open Cart 2. Inspect Quantity control | I6: - | J6: Quantity should be a dropdown with values 1 to 20. Changing it should update the line total and net total immediately. | K6: Quantity is a text box with an Update button, not a dropdown. | L6: QA - http://13.200.185.1/c/purushoth-kumar-efaa03 | Chrome, macOS | M6: Fail | N6: Medium | O6: DEF-004
A7: TC-03-02 | B7: Cart | C7: Buyer | D7: Quantity boundaries per line 1 and 99 (BR-03) | E7: Verify cart line quantity limits of 1 and 99. | F7: Boundary | G7: Cart has a line; product stock >= 99 units | H7: 1. Set qty 1 -> accepted 2. Set qty 99 (via product page) -> accepted 3. Set qty 100 -> rejected | I7: 1, 99, 100 | J7: Quantities 1 and 99 should be accepted. Quantity 100 should be rejected with a clear message, and the line should stay unchanged. | K7: Quantities 1 and 99 were accepted. Quantity 100 was rejected with a message, and the line stayed unchanged. | L7: QA - http://13.200.185.1/c/purushoth-kumar-efaa03 | Chrome, macOS | M7: Pass | N7: High
A8: TC-03-03 | B8: Cart | C8: Buyer | D8: Cannot add more pieces than in stock (BR-01) | E8: Verify a buyer cannot order more than the available stock. | F8: Negative | G8: Logged in as buyer1; SKU-0007 Pure Basmati Rice has 1 piece in stock (case of 12) | H8: 1. Open SKU-0007 Pure Basmati Rice 2. Choose Case, quantity 1 (12 pieces) 3. Click Add to cart | I8: SKU-0007 Pure Basmati Rice: stock 1 piece, case of 12 (try 1 case); SKU-0012 Farm Basmati Rice: stock 3, case 24 | J8: The add should be rejected with a 'not enough stock' message. The cart should never hold more pieces than are in stock. | K8: Adding more than the available stock of the Test Data products was rejected with a 'not enough stock' message. | L8: QA - http://13.200.185.1/c/purushoth-kumar-efaa03 | Chrome, macOS | M8: Pass | N8: High
A9: TC-04-01 | B9: Checkout | C9: Buyer | D9: One summary row per seller plus grand total (5.2) | E9: Verify checkout shows a summary per seller and a grand total. | F9: Positive | G9: Cart has items from FreshFarm Foods and WholeCart Direct | H9: 1. Proceed to checkout | I9: FreshFarm: Cardamom x2 case; WholeCart Direct: Butter case, Banana Chips case | J9: There should be one row per seller showing Net, Tax, Delivery (incl. tax) and Total. Grand total should equal the sum of the seller totals. | K9: One row per seller (FreshFarm ₹2,552.32, WholeCart Direct ₹2,004.82). Grand total ₹4,557.14 is correct. | L9: QA - http://13.200.185.1/c/purushoth-kumar-efaa03 | Chrome, macOS | M9: Pass | N9: High
A10: TC-04-02 | B10: Checkout | C10: Buyer | D10: Tax per rate on summed net, rounded half-up once per rate (BR-07) | E10: Verify tax is calculated and rounded per tax rate. | F10: Positive | G10: Seller sub-order with 5% and 18% lines | H10: 1. Add lines 2. Open checkout 3. Recalculate tax by hand | I10: Butter case ₹692.76 (5%) + Banana Chips case ₹982.56 (18%) | J10: Tax should be calculated on the total net of each tax rate and rounded half-up once per rate. For Butter (5%) and Banana Chips (18%), tax should be ₹34.64 + ₹176.86 = ₹211.50. | K10: Tax is correct. Example: ₹1,584.24 at 5% shows ₹79.21 (rounded once, as required). | L10: QA - http://13.200.185.1/c/purushoth-kumar-efaa03 | Chrome, macOS | M10: Pass | N10: High
A11: TC-04-03 | B11: Checkout | C11: Buyer | D11: Delivery fee ₹118 when seller net below ₹3,000 (BR-08) | E11: Verify the ₹118 delivery fee below ₹3,000 per seller. | F11: Positive | G11: Logged in as buyer1 (Spice Route Kitchen) / Test@123 | H11: 1. Checkout with seller net ₹2,318.40 | I11: - | J11: A delivery fee of ₹118.00 (₹100 + 18% tax) should be charged for each seller whose net is below ₹3,000. | K11: ₹118 fee charged when seller net is below ₹3,000; no fee above ₹3,000. | L11: QA - http://13.200.185.1/c/purushoth-kumar-efaa03 | Chrome, macOS | M11: Pass | N11: High
A12: TC-04-04 | B12: Checkout | C12: Buyer | D12: No delivery fee at net exactly ₹3,000.00 and above | E12: Verify no delivery fee at ₹3,000 and above. | F12: Boundary | G12: Logged in as buyer1 (Spice Route Kitchen) / Test@123 | H12: 1. Build seller nets ₹2,999.99 / ₹3,000.00 / ₹3,000.01 2. Check fee | I12: 2999.99, 3000.00, 3000.01 | J12: Delivery fee should be ₹118.00 at ₹2,999.99. It should be ₹0.00 at ₹3,000.00 and above. | K12: Delivery fee was ₹118.00 below ₹3,000 (e.g. ₹2,240.00 net) and ₹0.00 at exactly ₹3,000.00 net (Almond Oil 2 pieces, WC-01028-1) and above. | L12: QA - http://13.200.185.1/c/purushoth-kumar-efaa03 | Chrome, macOS | M12: Pass | N12: High
A13: TC-04-05 | B13: Checkout | C13: Buyer | D13: Seller net below ₹1,500 blocks checkout (BR-04) | E13: Verify checkout is blocked below the minimum order. | F13: Negative | G13: Logged in as buyer1 (Spice Route Kitchen) / Test@123 | H13: 1. Cart with one seller net ₹1,499.99 2. Place order | I13: WholeCart Direct net ₹1,385.52 (Chef's Cumin Seeds 1 case) | J13: The order should not be placed. The message should name the seller and state the ₹1,500 minimum. | K13: Order is blocked, but the message says the minimum is ₹2,000 instead of ₹1,500. | L13: QA - http://13.200.185.1/c/purushoth-kumar-efaa03 | Chrome, macOS | M13: Fail | N13: High | O13: DEF-011
A14: TC-04-06 | B14: Checkout | C14: Buyer | D14: Seller net exactly ₹1,500.00 allowed | E14: Verify an order of exactly the minimum is allowed. | F14: Boundary | G14: Logged in as buyer1 (Spice Route Kitchen) / Test@123 | H14: 1. Cart with seller net ₹1,500.00 2. Place order | I14: Seller net ₹1,500.00. 'Minimum order per seller' setting was ₹1,000 at the time of testing (default ₹2,000, see DEF-011). | J14: The order should be placed successfully at exactly ₹1,500.00 net. | K14: The order was placed successfully at ₹1,500.00 net. | L14: QA - http://13.200.185.1/c/purushoth-kumar-efaa03 | Chrome, macOS | M14: Pass | N14: High
A15: TC-04-07 | B15: Checkout | C15: Buyer | D15: Minimum checked per seller, not on the whole cart | E15: Verify the minimum order is checked for each seller. | F15: Negative | G15: Logged in as buyer1 (Spice Route Kitchen) / Test@123 | H15: 1. Seller A net ₹3,000, seller B net ₹500 2. Place order | I15: WC-01010: WholeCart Direct net ₹132.48 (Chef's Chana Dal 1 case) + Coastal Beverages ₹11,887.32 | J15: Checkout should be blocked when any one seller is below the minimum, even if the cart total is above it. The message should name that seller. | K15: Order WC-01010-1 was placed with only ₹132.48 for WholeCart Direct, below the minimum. | L15: QA - http://13.200.185.1/c/purushoth-kumar-efaa03 | Chrome, macOS | M15: Fail | N15: High | O15: DEF-010
A16: TC-04-08 | B16: Checkout | C16: Buyer | D16: Order split into one sub-order per seller with numbers WC-xxxxx-n (BR-09) | E16: Verify one sub-order is created per seller. | F16: Positive | G16: Cart with two sellers | H16: 1. Choose valid date and slot 2. Place order | I16: Delivery 2026-10-15 08:00-11:00 | J16: One sub-order should be created per seller, numbered with the same checkout number plus seller index (e.g. WC-01008-1, WC-01008-2). | K16: Two orders created: WC-01008-1 (WholeCart Direct) and WC-01008-2 (FreshFarm Foods). | L16: QA - http://13.200.185.1/c/purushoth-kumar-efaa03 | Chrome, macOS | M16: Pass | N16: High
A17: TC-04-09 | B17: Checkout | C17: Buyer | D17: Success message and redirect (5.2) | E17: Verify the order confirmation message and redirect. | F17: Positive | G17: Valid cart, date and slot | H17: 1. Place order | I17: - | J17: Buyer should be taken to Order history. Message should read 'Your order has been placed. Order number: WC-01008-1, WC-01008-2'. | K17: Goes to Order history, but the message is only 'Order placed!' with no order numbers. | L17: QA - http://13.200.185.1/c/purushoth-kumar-efaa03 | Chrome, macOS | M17: Fail | N17: Medium | O17: DEF-003
A18: TC-04-10 | B18: Checkout | C18: Buyer | D18: Cart is emptied after successful order | E18: Verify the cart is emptied after an order is placed. | F18: Positive | G18: Order just placed | H18: 1. Open Cart | I18: - | J18: The cart should be empty after the order is placed. | K18: Cart is empty after placing an order. | L18: QA - http://13.200.185.1/c/purushoth-kumar-efaa03 | Chrome, macOS | M18: Pass | N18: High
A19: TC-04-11 | B19: Checkout | C19: Buyer | D19: Double submit creates one order (BR-10) | E19: Verify a double-click on Place order creates one order. | F19: Negative | G19: Logged in as buyer1; cart has SKU-910 Almond Oil, 2 pieces | H19: 1. Proceed to checkout and choose a valid date and slot 2. Double-click Place order 3. Check Order history and the product stock | I19: SKU-910 Almond Oil, 2 pieces (stock 30) | J19: Only one order should be created. Order history should show one set of sub-orders, and stock should be reduced only once. | K19: Double-clicking Place order created two orders (WC-01028-1 and WC-01029-1, both ₹3,150.00). Stock dropped from 30 to 26, so it was deducted twice. | L19: QA - http://13.200.185.1/c/purushoth-kumar-efaa03 | Chrome, macOS | M19: Fail | N19: High | O19: DEF-018
A20: TC-04-12 | B20: Checkout | C20: Buyer | D20: Two buyers ordering the last stock at the same time (BR-01) | E20: Verify stock is not oversold when two buyers order together. | F20: Negative | G20: Product stock 6 pcs; buyer1 and buyer2 each have 1 case (6 pcs) in cart | H20: 1. Both place order at the same moment (parallel requests) | I20: buyer1, buyer2 | J20: Only one order should succeed. The other buyer should get a 'not enough stock' message, and stock should never go below zero. | K20: Only one order succeeded. The other buyer got a 'not enough stock' message, and stock did not go below zero. | L20: QA - http://13.200.185.1/c/purushoth-kumar-efaa03 | Chrome, macOS | M20: Pass | N20: High
A21: TC-05-01 | B21: Delivery Slots | C21: Buyer, Operator | D21: Delivery date allowed today to today+7 (BR-05) | E21: Verify delivery date is limited to today to today+7. | F21: Boundary | G21: Logged in as buyer1 (Spice Route Kitchen) / Test@123; Operator has fixed the store clock (BR-24) to the time given in Test Data | H21: 1. Pick today, today+7, today+8, yesterday 2. Show slots / place order | I21: Clock 2026-10-14 09:00 | J21: Dates from today to today+7 should be allowed. Yesterday and today+8 should be rejected with a clear reason. | K21: Today+8 (22/10/2026) is blocked with 'Delivery date must be within 7 days'. Dates within 7 days are allowed. | L21: QA - http://13.200.185.1/c/purushoth-kumar-efaa03 | Chrome, macOS | M21: Pass | N21: High
A22: TC-05-02 | B22: Delivery Slots | C22: Buyer | D22: Same-day morning slots always disabled with reason (BR-06) | E22: Verify same-day morning slots are disabled. | F22: Negative | G22: Logged in as buyer1 (Spice Route Kitchen) / Test@123 | H22: 1. Choose today 2. Show slots | I22: Today | J22: For today, the 08:00-11:00 and 11:00-14:00 slots should be disabled with the reason shown. | K22: Morning slots for today are disabled with a reason shown. | L22: QA - http://13.200.185.1/c/purushoth-kumar-efaa03 | Chrome, macOS | M22: Pass | N22: High
A23: TC-05-03 | B23: Delivery Slots | C23: Buyer, Operator | D23: Same-day slots disabled at and after cut-off 10:00 | E23: Verify same-day slots close at the 10:00 cut-off. | F23: Boundary | G23: Operator has fixed the store clock (BR-24) to the time given in Test Data | H23: 1. Choose today 2. Show slots 3. Try to post order with 14:00-17:00 anyway | I23: Clock 10:00:00 and 10:48 | J23: From 10:00, today's 14:00-17:00 and 17:00-20:00 slots should be disabled with the reason shown. A forced request should also be rejected by the server. | K23: After 10:00, today's afternoon and evening slots are disabled with 'Same-day orders must be placed before 10:00'. | L23: QA - http://13.200.185.1/c/purushoth-kumar-efaa03 | Chrome, macOS | M23: Pass | N23: High
A24: TC-05-04 | B24: Delivery Slots | C24: Buyer | D24: Slot full after 5 orders (BR-05) | E24: Verify a slot closes after 5 orders. | F24: Boundary | G24: 4 orders already in 2026-10-16 08:00-11:00 | H24: 1. Place 5th order in slot -> OK 2. Try 6th order in same slot | I24: Capacity 5 | J24: The 5th order should be accepted. After that the slot should show as full and a 6th order should be rejected. | K24: The 5th order was accepted. The slot then showed as full, and a 6th order was rejected. | L24: QA - http://13.200.185.1/c/purushoth-kumar-efaa03 | Chrome, macOS | M24: Pass | N24: High
A25: TC-06-01 | B25: Order History | C25: Buyer | D25: Cancelled orders stay listed with status Cancelled (BR-11) | E25: Verify cancelled orders stay in Order history. | F25: Positive | G25: One order cancelled | H25: 1. Open Orders | I25: WC-01008-1 | J25: The cancelled order should stay in Order history with status 'Cancelled' and its original total. | K25: Cancelled order WC-01008-1 stays in Order history with status 'cancelled'. | L25: QA - http://13.200.185.1/c/purushoth-kumar-efaa03 | Chrome, macOS | M25: Pass | N25: High
A26: TC-06-02 | B26: Order History | C26: Buyer | D26: Only actions valid for the status are shown | E26: Verify order detail shows only valid actions for its status. | F26: Negative | G26: Orders in placed, cancelled, delivered status | H26: 1. View each order | I26: - | J26: Cancel should show only for placed/accepted orders within 5 minutes. Redelivery should show only after a failed delivery. Refund/exchange should show only for delivered orders. Cancelled orders should show only Reorder. | K26: Cancelled, placed and delivered orders still show Cancel, Change slot, Redelivery and Refund buttons. | L26: QA - http://13.200.185.1/c/purushoth-kumar-efaa03 | Chrome, macOS | M26: Fail | N26: Medium | O26: DEF-005
A27: TC-06-03 | B27: Order History | C27: Buyer | D27: Money shown in rupee format with thousands separator | E27: Verify amounts use a thousands separator. | F27: Positive | G27: - | H27: 1. Compare amounts with FDD mock-ups | I27: - | J27: All amounts should be shown with a thousands separator, e.g. ₹2,552.32. | K27: Amounts show as ₹2552.32 instead of ₹2,552.32. | L27: QA - http://13.200.185.1/c/purushoth-kumar-efaa03 | Chrome, macOS | M27: Fail | N27: Low | O27: DEF-007
A28: TC-07-01 | B28: Cancellation | C28: Buyer | D28: Buyer cancels a placed order within 5 minutes | E28: Verify a buyer can cancel within 5 minutes. | F28: Positive | G28: Order placed < 5 min ago | H28: 1. View order 2. Cancel order | I28: WC-01008-1 placed 10:48:58 | J28: The order should be cancelled and its status should change to 'Cancelled'. It should stay in Order history, and its stock should be returned. | K28: Order cancelled within 5 minutes; status changed to 'cancelled'. | L28: QA - http://13.200.185.1/c/purushoth-kumar-efaa03 | Chrome, macOS | M28: Pass | N28: High
A29: TC-07-02 | B29: Cancellation | C29: Buyer, Operator | D29: Cancel at exactly 5:00 allowed, 5:01 rejected (BR-11) | E29: Verify the 5-minute cancel boundary. | F29: Boundary | G29: Operator has fixed the store clock (BR-24) to the time given in Test Data | H29: 1. Place order at T 2. Set clock T+5:00, cancel -> OK 3. New order, clock T+5:01, cancel | I29: T = 2026-10-14 09:00:00 | J29: Cancel at exactly 5 minutes 0 seconds should succeed. Cancel at 5 minutes 1 second should be rejected with the 'within 5 minutes' message. | K29: Cancel at exactly 5 minutes succeeded. Cancel at 5 minutes 1 second was rejected with the 'within 5 minutes' message. | L29: QA - http://13.200.185.1/c/purushoth-kumar-efaa03 | Chrome, macOS | M29: Pass | N29: High
A30: TC-07-03 | B30: Cancellation | C30: Buyer | D30: Cancel after 5 minutes rejected | E30: Verify cancel is rejected after 5 minutes. | F30: Negative | G30: Order placed > 5 min ago | H30: 1. View order 2. Cancel order | I30: WC-01007-1 placed 10:44:06, tried ~10:50 | J30: Cancel should be rejected with the 'within 5 minutes' message, and the order status should stay unchanged. | K30: Cancel after 5 minutes is rejected with 'Orders can only be cancelled within 5 minutes'. | L30: QA - http://13.200.185.1/c/purushoth-kumar-efaa03 | Chrome, macOS | M30: Pass | N30: High
A31: TC-07-04 | B31: Cancellation | C31: Buyer | D31: Stock returned on cancellation | E31: Verify stock is returned when an order is cancelled. | F31: Positive | G31: Stock S before order of 12 pcs | H31: 1. Place order 2. Cancel 3. Check stock | I31: - | J31: Stock of every product in the cancelled order should go back to the level before the order. | K31: Stock of every product in the cancelled order went back to the level before the order. | L31: QA - http://13.200.185.1/c/purushoth-kumar-efaa03 | Chrome, macOS | M31: Pass | N31: High
A32: TC-07-05 | B32: Cancellation | C32: Buyer, Seller | D32: Seller cancels; buyer sees Cancelled immediately (BR-12) | E32: Verify a seller cancellation shows to the buyer immediately. | F32: Positive | G32: Placed order for seller2 | H32: 1. seller2 cancels 2. buyer1 refreshes Orders | I32: WC-01012-1 (accepted), WC-01010-1 (placed), WC-01009-1 cancelled by seller1 | J32: The buyer should see status 'Cancelled' straight away in Order history and order detail. Stock should be returned. | K32: Seller cancelled WC-01012-1 and WC-01010-1, but the buyer still sees them as 'accepted' and 'placed'. | L32: QA - http://13.200.185.1/c/purushoth-kumar-efaa03 | Chrome, macOS | M32: Fail | N32: High | O32: DEF-009
A33: TC-08-01 | B33: Slot Change | C33: Buyer | D33: Buyer changes slot before shipping (BR-15) | E33: Verify a buyer can change the delivery slot before shipping. | F33: Positive | G33: Order placed/accepted | H33: 1. View order 2. Choose new date/slot 3. Change slot | I33: 2026-10-16 14:00-17:00 | J33: The new date and slot should be saved and shown in the order detail, Order history and the seller's order list. | K33: The slot was changed to 2026-10-16 14:00-17:00 and shown in the order detail, Order history and the seller's order list. | L33: QA - http://13.200.185.1/c/purushoth-kumar-efaa03 | Chrome, macOS | M33: Pass | N33: High
A34: TC-08-02 | B34: Slot Change | C34: Buyer | D34: Slot form defaults to current delivery | E34: Verify the slot form shows the order's current delivery. | F34: Positive | G34: Order delivery 2026-10-15 08:00-11:00 | H34: 1. View order | I34: - | J34: The Change slot form should be pre-filled with the order's current delivery date and slot. | K34: Form shows today's date (14/10/2026) instead of the order's delivery date (15/10/2026). | L34: QA - http://13.200.185.1/c/purushoth-kumar-efaa03 | Chrome, macOS | M34: Fail | N34: Low | O34: DEF-008
A35: TC-09-01 | B35: Redelivery | C35: Buyer | D35: Request redelivery after failed delivery (BR-14) | E35: Verify a buyer can request redelivery after a failed delivery. | F35: Positive | G35: Seller marked order 'delivery failed' | H35: 1. Buyer views order 2. Choose new valid slot 3. Request redelivery | I35: WC-01011-1 is now 'delivery_failed' (seller1 marked Fail) | J35: The new slot should be saved and the status should change to 'redelivery requested'. The order should appear in the logistics export. | K35: For WC-01011-1, the new slot was saved and the status changed to 'redelivery requested'. | L35: QA - http://13.200.185.1/c/purushoth-kumar-efaa03 | Chrome, macOS | M35: Pass | N35: High
A36: TC-10-01 | B36: Reorder | C36: Buyer | D36: Reorder adds every line with the original quantity (BR-16) | E36: Verify Reorder adds all lines with original quantities. | F36: Positive | G36: Cart empty; past orders delivered/placed | H36: 1. Orders > Reorder on a past order 2. Open Cart | I36: buyer1: WC-01008-2 (Chef's Cardamom 2 cases). buyer2: WC-01021-1 (Basmati Rice 27 + Almond seeds 5), WC-01001-1 (Spice Basmati Rice 1, Daily Toor Dal 1, Royal Moong Dal 3), WC-01003-1 (Fresh Orange Juice 2, Farm Orange Juice 1, Chef's Cold Coffee 2) | J36: Every line of the past order should be added to the cart with the same quantity as the original order. | K36: Quantities are correct, but the last line of the order is missing from the cart (Almond seeds, Royal Moong Dal, Chef's Cold Coffee). | L36: QA - http://13.200.185.1/c/purushoth-kumar-efaa03 | Chrome, macOS | M36: Fail | N36: High | O36: DEF-015
A37: TC-10-02 | B37: Reorder | C37: Buyer | D37: Reorder a multi-line order | E37: Verify Reorder of an order with several lines. | F37: Positive | G37: Cart has Cardamom | H37: 1. Reorder WC-01008-1 | I37: Butter case x1, Banana Chips case x1 | J37: All lines of the order should be added to the cart. Existing cart lines should be kept, and the message should show the correct number of items added. | K37: WC-01001-1 and WC-01003-1 each had 3 lines; Reorder added only 2. The last line was missing. | L37: QA - http://13.200.185.1/c/purushoth-kumar-efaa03 | Chrome, macOS | M37: Fail | N37: High | O37: DEF-015
A38: TC-11-01 | B38: Refunds & Exchanges | C38: Buyer | D38: Refund/exchange only for delivered orders (BR-17) | E38: Verify refunds and exchanges are allowed only for delivered orders. | F38: Negative | G38: Orders placed, shipped, cancelled | H38: 1. Try Send request on each | I38: - | J38: Refund and exchange should only be possible for delivered orders. For placed, shipped and cancelled orders the form should be hidden or the request rejected. | K38: Refund/exchange form is shown on placed and cancelled orders. | L38: QA - http://13.200.185.1/c/purushoth-kumar-efaa03 | Chrome, macOS | M38: Fail | N38: High | O38: DEF-005
A39: TC-11-02 | B39: Refunds & Exchanges | C39: Buyer, Seller | D39: Partial refund amount includes tax on refunded qty (BR-18) | E39: Verify the partial refund amount includes tax. | F39: Positive | G39: Delivered order, Banana Chips case x2 | H39: 1. Partial refund 1 case 2. Seller approves | I39: WC-01007-1 (delivered): refund 1 case Chef's Banana Chips ₹982.56 @18% | J39: Refund for 1 case of Banana Chips should be ₹982.56 + ₹176.86 tax = ₹1,159.42. | K39: For WC-01007-1, the refund for 1 case of Chef's Banana Chips was ₹1,159.42 (₹982.56 + ₹176.86 tax). | L39: QA - http://13.200.185.1/c/purushoth-kumar-efaa03 | Chrome, macOS | M39: Pass | N39: High
A40: TC-11-03 | B40: Refunds & Exchanges | C40: Buyer, Seller | D40: Total refunded/exchanged per line never exceeds ordered qty | E40: Verify refunds cannot exceed the ordered quantity. | F40: Boundary | G40: Delivered line qty 2 | H40: 1. Partial refund 1 2. Exchange 1 3. Try another refund of 1 | I40: qty 2 | J40: Requests should be accepted until the ordered quantity is used up. Any request beyond it should be rejected. | K40: For a line with quantity 2, requests were accepted up to 2. A further request was rejected. | L40: QA - http://13.200.185.1/c/purushoth-kumar-efaa03 | Chrome, macOS | M40: Pass | N40: High
...

Sheet Bugs
A1: Defect ID | B1: Module | C1: Bug Summary | D1: Bug Description | E1: Preconditions | F1: Steps to Reproduce | G1: Test Data | H1: Expected Result | I1: Actual Result | J1: Severity | K1: Priority | L1: Evidence | M1: Linked Test Cases | N1: Environment | O1: Status | P1: Reported Date
A2: DEF-001 | B2: Monthly Statements | C2: Monthly statement includes a cancelled order and charges it in Amount due | D2: Cancelled orders should not be on the statement, but WC-01008-1 is listed and charged ₹2,004.82. | E2: Logged in as buyer1 (Spice Route Kitchen) / Test@123; WC-01008-1 placed and cancelled within 5 minutes | F2: 1. Place an order (WC-01008-1, ₹2,004.82) 2. Cancel it within 5 minutes 3. Statements > October 2026 > Show | G2: WC-01008-1, ₹2,004.82, October 2026 | H2: Cancelled orders should not appear on the statement. Orders total and Amount due should be ₹0.00 when no orders are delivered. | I2: Cancelled order WC-01008-1 is listed on the October statement with status 'cancelled', and ₹2,004.82 is added to Orders total and Amount due. | J2: Critical | K2: High | L2: evidence/DEF-001_statement_cancelled.mp4 | M2: TC-13-01, TC-13-02 | N2: QA - http://13.200.185.1/c/purushoth-kumar-efaa03 | Chrome, macOS | O2: Open | P2: 46309
A3: DEF-003 | B3: Checkout | C3: Order success message does not show order numbers | D3: Message should include the order numbers; only 'Order placed!' is shown. | E3: Logged in as buyer1 (Spice Route Kitchen) / Test@123; valid cart with 2 sellers | F3: 1. Checkout, choose 2026-10-15 08:00-11:00 2. Place order | G3: FreshFarm + WholeCart Direct cart | H3: After placing an order the buyer should see 'Your order has been placed. Order number: WC-01008-1, WC-01008-2'. | I3: Buyer is taken to Order history, but the message shows only 'Order placed!' without the order numbers. | J3: Minor | K3: Medium | L3: evidence/DEF-003_order_placed_msg.mp4 | M3: TC-04-09 | N3: QA - http://13.200.185.1/c/purushoth-kumar-efaa03 | Chrome, macOS | O3: Open | P3: 46309
A4: DEF-004 | B4: Cart | C4: Cart quantity is a free-text box, not a 1-20 dropdown | D4: Quantity should be a 1-20 dropdown; it is a text box with an Update button. | E4: Logged in as buyer1 (Spice Route Kitchen) / Test@123; cart has lines | F4: 1. Open Cart 2. Look at Quantity | G4: - | H4: Quantity should be a dropdown with values 1 to 20, and changing it should update the line straight away. | I4: Quantity is a text box with a separate Update button, so any value can be typed. | J4: Minor | K4: Medium | L4: evidence/DEF-004_cart_qty_textbox.mp4 | M4: TC-03-01 | N4: QA - http://13.200.185.1/c/purushoth-kumar-efaa03 | Chrome, macOS | O4: Open | P4: 46309
A5: DEF-005 | B5: Order History | C5: Order detail shows actions that are not valid for the status | D5: Cancel, Change slot, Redelivery and Refund buttons show on cancelled, placed and delivered orders. | E5: Logged in as buyer1 (Spice Route Kitchen) / Test@123 | F5: 1. Cancel WC-01008-1 2. View it 3. Click Cancel order again 4. Also view placed order WC-01007-1 | G5: WC-01008-1 (cancelled), WC-01007-1 (placed), WC-01021-1 (delivered) | H5: Each order should show only the actions valid for its status. Cancelled orders should show only Reorder, and Refund should show only on delivered orders. | I5: Cancel order, Change slot, Request redelivery and Refund buttons are shown on cancelled, placed and delivered orders. Clicking Cancel on a cancelled order says 'This order can no longer be cancelled'. | J5: Minor | K5: Medium | L5: evidence/DEF-005_cancelled_actions.mp4 | M5: TC-06-02, TC-11-01 | N5: QA - http://13.200.185.1/c/purushoth-kumar-efaa03 | Chrome, macOS | O5: Open | P5: 46309
A6: DEF-006 | B6: Catalogue & Search | C6: Category filter is ignored when combined with search text | D6: Search 'Chef' + category 'Oils' still shows all categories. | E6: Logged in as buyer1 (Spice Route Kitchen) / Test@123 | F6: 1. Catalogue 2. Search 'Chef', All categories -> 28 products 3. Select 'Oils', click Search | G6: Chef + Oils | H6: Only products matching both the search text and the category should be shown, and the count should match. | I6: After searching 'Chef' with category 'Oils', the list still shows 28 products from Snacks, Grains, Dairy and Spices. | J6: Major | K6: High | L6: evidence/DEF-006_category_filter.mp4 | M6: TC-02-02 | N6: QA - http://13.200.185.1/c/purushoth-kumar-efaa03 | Chrome, macOS | O6: Open | P6: 46309
A7: DEF-007 | B7: Order History | C7: Amounts shown without thousands separator | D7: Amounts show as ₹2552.32 instead of ₹2,552.32. | E7: Logged in as buyer1 (Spice Route Kitchen) / Test@123 | F7: 1. Look at amounts on Cart, Checkout, Orders | G7: - | H7: Amounts should be shown with a thousands separator, e.g. ₹2,552.32. | I7: Amounts are shown without a separator, e.g. ₹2552.32 on cart, checkout and Order history. | J7: Trivial | K7: Low | L7: evidence/DEF-003_order_placed_msg.mp4 | M7: TC-06-03 | N7: QA - http://13.200.185.1/c/purushoth-kumar-efaa03 | Chrome, macOS | O7: Open | P7: 46309
A8: DEF-008 | B8: Slot Change | C8: Change-slot form pre-filled with today's date instead of the order's delivery date | D8: Change slot form shows today's date, not the order's delivery date. | E8: Logged in as buyer1 (Spice Route Kitchen) / Test@123 | F8: 1. View order WC-01008-1 (delivery 2026-10-15 08:00-11:00) | G8: - | H8: The Change slot form should show the order's current delivery date and slot. | I8: Change slot form shows today's date (14/10/2026) and 08:00-11:00 instead of the order's delivery date (15/10/2026). | J8: Trivial | K8: Low | L8: evidence/DEF-005_cancelled_actions.mp4 | M8: TC-08-02 | N8: QA - http://13.200.185.1/c/purushoth-kumar-efaa03 | Chrome, macOS | O8: Open | P8: 46309
A9: DEF-009 | B9: Cancellation | C9: Seller cancellation is not shown to the buyer (BR-12) | D9: Seller cancelled the order, but the buyer still sees 'accepted' / 'placed'. | E9: seller1 and buyer1 logged in (separate browsers) | F9: 1. seller1 cancels WC-01012-1 (accepted) and WC-01010-1 (placed) 2. buyer1 opens Orders and the order detail | G9: WC-01012-1 (accepted), WC-01010-1 (placed) | H9: When a seller cancels, the buyer should see 'Cancelled' immediately and the stock should be returned. | I9: Seller's list shows WC-01012-1 and WC-01010-1 as 'cancelled', but the buyer still sees them as 'accepted' and 'placed'. Buyer's own Cancel fails with 'This order can no longer be cancelled'. | J9: Critical | K9: High | L9: evidence/DEF-009_seller_view.mp4; evidence/DEF-009_buyer_view.mp4 | M9: TC-07-05 | N9: QA - http://13.200.185.1/c/purushoth-kumar-efaa03 | Chrome, macOS | O9: Open | P9: 46309
A10: DEF-010 | B10: Checkout | C10: Minimum order per seller not enforced in a multi-seller checkout (BR-04) | D10: WC-01010-1 was placed with ₹132.48 net, below the per-seller minimum. | E10: buyer1; cart with WholeCart Direct item below minimum + Coastal Beverages items above minimum | F10: 1. Add Chef's Chana Dal 1 case (₹132.48, WholeCart Direct) 2. Add Coastal Beverages items (> ₹11,000) 3. Place order | G10: WC-01010-1 net ₹132.48, WC-01010-2 ₹11,887.32 | H10: Checkout should be blocked when any seller's net is below the minimum, and the message should name that seller. | I10: Order WC-01010-1 for WholeCart Direct was placed with only ₹132.48 net (total ₹257.10), because the other seller in the same checkout was above the minimum. | J10: Major | K10: High | L10: evidence/DEF-010_min_order_bypass.mp4 | M10: TC-04-07 | N10: QA - http://13.200.185.1/c/purushoth-kumar-efaa03 | Chrome, macOS | O10: Open | P10: 46309
A11: DEF-011 | B11: Checkout | C11: Default 'Minimum order per seller' is ₹2,000; design says ₹1,500 (BR-04) | D11: Minimum order is set to ₹2,000; design says ₹1,500. | E11: operator and buyer1 | F11: 1. Operator: open Settings, read Minimum order per seller 2. Buyer: cart Chef's Cumin Seeds 1 case (₹1,385.52), place order | G11: Setting ₹2,000; net ₹1,385.52 | H11: The minimum order per seller should be ₹1,500 as per the design, so orders from ₹1,500 should be allowed. | I11: Operator setting 'Minimum order per seller' is ₹2,000, and checkout shows 'Minimum order value is ₹2000 per seller'. | J11: Major | K11: High | L11: evidence/DEF-011_checkout_min_2000.mp4 ; evidence/DEF-011_settings_min_2000.mp4 | M11: TC-04-05 | N11: QA - http://13.200.185.1/c/purushoth-kumar-efaa03 | Chrome, macOS | O11: Open | P11: 46309
A12: DEF-012 | B12: Seller - Products | C12: Product list Next link opens an empty page after the last page | D12: Next on the last page opens an empty product list. | E12: Logged in as seller1 | F12: 1. Products 2. Click Next past the last page | G12: - | H12: Next should be hidden or disabled on the last page. | I12: Clicking Next on the last page of the seller's product list opens an empty table with only Previous and Next links. | J12: Minor | K12: Low | L12: evidence/DEF-012_products_empty_page.mp4 | M12: TC-16-01 | N12: QA - http://13.200.185.1/c/purushoth-kumar-efaa03 | Chrome, macOS | O12: Open | P12: 46309
A13: DEF-013 | B13: Seller - CSV Import | C13: Upload without a file shows a misleading column error | D13: Upload with no file says 'CSV must have columns' instead of 'choose a file'. | E13: Logged in as seller1 | F13: 1. Products 2. Leave 'No file chosen' 3. Click Upload | G13: - | H13: The page should ask the seller to choose a CSV file. | I13: With no file chosen, clicking Upload shows 'CSV must have columns: sku, name, category, ...'. | J13: Trivial | K13: Low | L13: evidence/DEF-013_upload_no_file.mp4 | M13: TC-17-03 | N13: QA - http://13.200.185.1/c/purushoth-kumar-efaa03 | Chrome, macOS | O13: Open | P13: 46309
... A23: DEF-024 | B23: Invoices | C23: Invoice total amount text is barely visible | D23: On the invoice page, the Total amount is shown in very faint text and is hard to read. | E23: Buyer should have one delivered order | F23: 1. Log in as buyer 2. Orders > View a delivered order 3. Click the Invoice link 4. Look at the Total next to Net and Tax | G23: INV-00045 / WC-01040-1 | H23: The Total should be shown in clearly readable text, at least as visible as Net and Tax. | I23: The Total ₹2,470.00 is shown in very light text on a white background and is almost invisible. | J23: Minor | K23: Low | L23: evidence/DEF-022_invoice_fee_missing_total_faded.png | M23: TC-12-01 | N23: QA - http://13.200.185.1/c/purushoth-kumar-efaa03 | Chrome, macOS | O23: Open | P23: 46309

Sheet Questions & Assumptions
A1: # | B1: Area | C1: Question for the product owner | D1: Assumption used | E1: Related
A2: 1 | B2: Release notes | C2: The design doc says approved changes after v1.0 are in the Release notes. Which v1.0 rules have changed? | D2: Tested against design v1.0. Any defect that an approved release note covers (e.g. DEF-011) should be closed. | E2: All
A3: 2 | B3: BR-04 Minimum order | C3: The app enforces ₹2,000 per seller by default; the design says ₹1,500. Which is correct? | D3: ₹1,500 is the requirement (logged as DEF-011). | E3: DEF-011, TC-04-05
A4: 3 | B4: BR-04 Multi-seller checkout | C4: If one seller in a checkout is below the minimum, should the whole checkout be blocked or only that seller's sub-order? | D4: The whole checkout is blocked, with a message naming the seller. | E4: DEF-010, TC-04-07
A5: 4 | B5: BR-11 / BR-04 Operator settings | C5: Operator settings let the cancellation window and minimum order be changed, but the design states them as fixed (5 minutes, ₹1,500). Are they meant to be configurable? | D5: Yes, they are configurable (BR-23), but the design values are the defaults to test against. | E5: TC-19-03, TC-19-04
A6: 5 | B6: Pilot OPS-14 | C6: The settings page shows 'buyer3 has free delivery until 31 Oct 2026'. This is not in the design. Does it waive the full ₹118 fee, and should the invoice show a ₹0 fee line? | D6: buyer3 pays ₹0 delivery until 31 Oct inclusive; normal BR-08 rules apply from 1 Nov. | E6: TC-19-05
A7: 6 | B7: BR-16 Reorder and existing cart | C7: Should Reorder add the past order's lines to items already in the cart, or replace the cart? | D7: Lines are added to the existing cart, as BR-16 says 'adds every line… to the cart'. | E7: TC-10-02
A8: 7 | B8: BR-16 Reorder and stock | C8: What should Reorder do when a line cannot be filled from current stock? | D8: Add what it can and tell the buyer which line was skipped. | E8: DEF-015
A9: 8 | B9: BR-06 Cut-off boundary | C9: Is an order at exactly 10:00:00 'before the cut-off'? | D9: 09:59:59 is allowed; 10:00:00 is not. | E9: TC-05-03
A10: 9 | B10: BR-08 Fee boundary | C10: Is the delivery fee charged at exactly ₹3,000.00 net? | D10: No fee at ₹3,000.00 and above. | E10: TC-04-04
A11: 10 | B11: BR-05 Slot capacity | C11: Is slot capacity counted per sub-order or per checkout, and does a cancelled order free its place? | D11: Each sub-order counts as one order; cancelled orders free the place. | E11: TC-05-04
A12: 11 | B12: BR-17 / BR-18 Refunds | C12: Is the delivery fee refunded on a full refund? Does a rejected request free its quantity for a new request? | D12: The delivery fee is not refunded; a rejected quantity can be requested again. | E12: TC-11-02, TC-11-03
A13: 12 | B13: BR-20 Statement month | C13: Is an order included by its delivery date, and is a refund deducted in the month it is approved? | D13: Delivery date; refunds in the month approved. | E13: TC-13-01
... A17: 16 | B17: Money format | C17: Mock-ups show ₹2,436.40 but the app shows ₹2436.40. Is the separator required? | D17: Yes, the mock-up format is the requirement (logged as DEF-007). | E17: DEF-007
